Workbook

Sheet 03_Historical_FS
A1: MWG - Historical Financial Statements (VND bn)
A2: Period: 2022A-2025A | Unit: VND bn ; Green = linked raw data ; Black = calculations
A4: Section | B4: Line Item | C4: Unit | D4: 2021A | E4: 2022A | F4: 2023A | G4: 2024A | H4: 2025A | I4: Source Sheet | J4: Source item_id
A5: INCOME STATEMENT
B6: Gross Revenue | C6: VND bn | D6: 124141.53 | E6: =IFERROR('90_Raw_IS_vnstock'!F2/1000000000,0) -> 134722.25 | F6: =IFERROR('90_Raw_IS_vnstock'!E2/1000000000,0) -> 119234.18 | G6: =IFERROR('90_Raw_IS_vnstock'!D2/1000000000,0) -> 135225.1 | H6: =IFERROR('90_Raw_IS_vnstock'!C2/1000000000,0) -> 156836.12 | I6: 90_Raw_IS_vnstock | J6: revenue
B7: Revenue | C7: VND bn | D7: 122958.11 | E7: =IFERROR('90_Raw_IS_vnstock'!F4/1000000000,0) -> 133404.78 | F7: =IFERROR('90_Raw_IS_vnstock'!E4/1000000000,0) -> 118279.79 | G7: =IFERROR('90_Raw_IS_vnstock'!D4/1000000000,0) -> 134341.15 | H7: =IFERROR('90_Raw_IS_vnstock'!C4/1000000000,0) -> 155928.15 | I7: 90_Raw_IS_vnstock | J7: revenue
B8: COGS | C8: VND bn | D8: 95325.974 | E8: =IFERROR('90_Raw_IS_vnstock'!F5/1000000000,0) -> 102542.74 | F8: =IFERROR('90_Raw_IS_vnstock'!E5/1000000000,0) -> 95759.175 | G8: =IFERROR('90_Raw_IS_vnstock'!D5/1000000000,0) -> 106841.94 | H8: =IFERROR('90_Raw_IS_vnstock'!C5/1000000000,0) -> 124926.27 | I8: 90_Raw_IS_vnstock | J8: cost_of_goods_sold
B9: Gross Profit | C9: VND bn | D9: 27632.132 | E9: =IFERROR('90_Raw_IS_vnstock'!F6/1000000000,0) -> 30862.042 | F9: =IFERROR('90_Raw_IS_vnstock'!E6/1000000000,0) -> 22520.613 | G9: =IFERROR('90_Raw_IS_vnstock'!D6/1000000000,0) -> 27499.21 | H9: =IFERROR('90_Raw_IS_vnstock'!C6/1000000000,0) -> 31001.877 | I9: 90_Raw_IS_vnstock | J9: gross_profit
B10: Gross Margin | C10: % | D10: 0.22472802 | E10: =IFERROR(E9/E7,0) -> 0.23134136 | F10: =IFERROR(F9/F7,0) -> 0.1904012 | G10: =IFERROR(G9/G7,0) -> 0.20469684 | H10: =IFERROR(H9/H7,0) -> 0.19882156 | I10: Formula
B11: Financial Income | C11: VND bn | D11: 1287.956 | E11: =IFERROR('90_Raw_IS_vnstock'!F8/1000000000,0) -> 1313.1373 | F11: =IFERROR('90_Raw_IS_vnstock'!E8/1000000000,0) -> 2166.9637 | G11: =IFERROR('90_Raw_IS_vnstock'!D8/1000000000,0) -> 2376.5026 | H11: =IFERROR('90_Raw_IS_vnstock'!C8/1000000000,0) -> 3107.3487 | I11: 90_Raw_IS_vnstock | J11: financial_income
B12: Finance Expenses | C12: VND bn | D12: 714.70723 | E12: =IFERROR('90_Raw_IS_vnstock'!F9/1000000000,0) -> 1382.6205 | F12: =IFERROR('90_Raw_IS_vnstock'!E9/1000000000,0) -> 1556.1461 | G12: =IFERROR('90_Raw_IS_vnstock'!D9/1000000000,0) -> 1188.4656 | H12: =IFERROR('90_Raw_IS_vnstock'!C9/1000000000,0) -> 1542.5187 | I12: 90_Raw_IS_vnstock | J12: finance_expenses
B13: Interest Expense | C13: VND bn | D13: 674.42775 | E13: =IFERROR('90_Raw_IS_vnstock'!F10/1000000000,0) -> 1362.1439 | F13: =IFERROR('90_Raw_IS_vnstock'!E10/1000000000,0) -> 1447.7184 | G13: =IFERROR('90_Raw_IS_vnstock'!D10/1000000000,0) -> 1137.2361 | H13: =IFERROR('90_Raw_IS_vnstock'!C10/1000000000,0) -> 1470.6756 | I13: 90_Raw_IS_vnstock | J13: of_which_interest_expense
B14: Selling Expenses | C14: VND bn | D14: 17914.173 | E14: =IFERROR('90_Raw_IS_vnstock'!F12/1000000000,0) -> 22336.838 | F14: =IFERROR('90_Raw_IS_vnstock'!E12/1000000000,0) -> 20916.711 | G14: =IFERROR('90_Raw_IS_vnstock'!D12/1000000000,0) -> 19849.838 | H14: =IFERROR('90_Raw_IS_vnstock'!C12/1000000000,0) -> 19330.904 | I14: 90_Raw_IS_vnstock | J14: selling_expenses
B15: G&A Expenses | C15: VND bn | D15: 3823.3901 | E15: =IFERROR('90_Raw_IS_vnstock'!F13/1000000000,0) -> 1881.0276 | F15: =IFERROR('90_Raw_IS_vnstock'!E13/1000000000,0) -> 1167.6517 | G15: =IFERROR('90_Raw_IS_vnstock'!D13/1000000000,0) -> 3565.7676 | H15: =IFERROR('90_Raw_IS_vnstock'!C13/1000000000,0) -> 4596.0745 | I15: 90_Raw_IS_vnstock | J15: admin_expenses
B16: Operating Expenses | C16: VND bn | D16: 21737.563 | E16: =E14+E15 -> 24217.866 | F16: =F14+F15 -> 22084.362 | G16: =G14+G15 -> 23415.605 | H16: =H14+H15 -> 23926.978 | I16: Formula
B17: EBIT | C17: VND bn | D17: 6465.6069 | E17: =IFERROR('90_Raw_IS_vnstock'!F14/1000000000,0) -> 6574.6937 | F17: =IFERROR('90_Raw_IS_vnstock'!E14/1000000000,0) -> 1047.0684 | G17: =IFERROR('90_Raw_IS_vnstock'!D14/1000000000,0) -> 5227.0454 | H17: =IFERROR('90_Raw_IS_vnstock'!C14/1000000000,0) -> 8664.0805 | I17: 90_Raw_IS_vnstock | J17: operating_profit
B18: EBIT Margin | C18: % | D18: 0.05258382 | E18: =IFERROR(E17/E7,0) -> 0.049283795 | F18: =IFERROR(F17/F7,0) -> 0.0088524706 | G18: =IFERROR(G17/G7,0) -> 0.038908743 | H18: =IFERROR(H17/H7,0) -> 0.055564571 | I18: Formula
B19: Other Profit | C19: VND bn | D19: 5.9768322 | E19: =IFERROR('90_Raw_IS_vnstock'!F17/1000000000,0) -> -518.33833 | F19: =IFERROR('90_Raw_IS_vnstock'!E17/1000000000,0) -> -357.37599 | G19: =IFERROR('90_Raw_IS_vnstock'!D17/1000000000,0) -> -401.28241 | H19: =IFERROR('90_Raw_IS_vnstock'!C17/1000000000,0) -> -31.012906 | I19: 90_Raw_IS_vnstock | J19: other_profit
B20: Profit Before Tax | C20: VND bn | D20: 6471.5838 | E20: =IFERROR('90_Raw_IS_vnstock'!F19/1000000000,0) -> 6056.3554 | F20: =IFERROR('90_Raw_IS_vnstock'!E19/1000000000,0) -> 689.69237 | G20: =IFERROR('90_Raw_IS_vnstock'!D19/1000000000,0) -> 4825.763 | H20: =IFERROR('90_Raw_IS_vnstock'!C19/1000000000,0) -> 8633.0676 | I20: 90_Raw_IS_vnstock | J20: profit_before_tax
B21: Current Tax Expense | C21: VND bn | D21: 1632.9757 | E21: =IFERROR('90_Raw_IS_vnstock'!F20/1000000000,0) -> 1792.9988 | F21: =IFERROR('90_Raw_IS_vnstock'!E20/1000000000,0) -> 433.25718 | G21: =IFERROR('90_Raw_IS_vnstock'!D20/1000000000,0) -> 1282.5371 | H21: =IFERROR('90_Raw_IS_vnstock'!C20/1000000000,0) -> 1721.5595 | I21: 90_Raw_IS_vnstock | J21: current_corporate_income_tax_expenses
B22: Deferred Tax Expense | C22: VND bn | D22: -62.818619 | E22: =IFERROR('90_Raw_IS_vnstock'!F21/1000000000,0) -> 161.64214 | F22: =IFERROR('90_Raw_IS_vnstock'!E21/1000000000,0) -> 88.606036 | G22: =IFERROR('90_Raw_IS_vnstock'!D21/1000000000,0) -> -190.06233 | H22: =IFERROR('90_Raw_IS_vnstock'!C21/1000000000,0) -> -161.11483 | I22: 90_Raw_IS_vnstock | J22: deferred_income_tax_expenses
B23: Total Tax Expense | C23: VND bn | D23: 1570.1571 | E23: =E21+E22 -> 1954.6409 | F23: =F21+F22 -> 521.86321 | G23: =G21+G22 -> 1092.4748 | H23: =H21+H22 -> 1560.4447 | I23: Formula
B24: NPAT | C24: VND bn | D24: 4901.4267 | E24: =IFERROR('90_Raw_IS_vnstock'!F22/1000000000,0) -> 4101.7144 | F24: =IFERROR('90_Raw_IS_vnstock'!E22/1000000000,0) -> 167.82915 | G24: =IFERROR('90_Raw_IS_vnstock'!D22/1000000000,0) -> 3733.2882 | H24: ='06_Revenue_Drivers_Hist'!H9 -> 7072.6229 | I24: 90_Raw_IS_vnstock | J24: net_profit
B25: Minority Interest - IS | C25: VND bn | D25: 2.5573957 | E25: =IFERROR('90_Raw_IS_vnstock'!F23/1000000000,0) -> 1.951398 | F25: =IFERROR('90_Raw_IS_vnstock'!E23/1000000000,0) -> 0.159762 | G25: =IFERROR('90_Raw_IS_vnstock'!D23/1000000000,0) -> 11.419787 | H25: =IFERROR('90_Raw_IS_vnstock'!C23/1000000000,0) -> 38.892116 | I25: 90_Raw_IS_vnstock | J25: minority_interest
B26: NPATMI | C26: VND bn | D26: 4898.8693 | E26: =IFERROR('90_Raw_IS_vnstock'!F24/1000000000,0) -> 4099.763 | F26: =IFERROR('90_Raw_IS_vnstock'!E24/1000000000,0) -> 167.66939 | G26: =IFERROR('90_Raw_IS_vnstock'!D24/1000000000,0) -> 3721.8684 | H26: =IFERROR('90_Raw_IS_vnstock'!C24/1000000000,0) -> 7033.7308 | I26: 90_Raw_IS_vnstock | J26: profit_after_tax_for_shareholders_of_parent_company
B27: NPATMI Margin | C27: % | D27: 0.039841776 | E27: =IFERROR(E26/E7,0) -> 0.030731756 | F27: =IFERROR(F26/F7,0) -> 0.0014175659 | G27: =IFERROR(G26/G7,0) -> 0.027704604 | H27: =IFERROR(H26/H7,0) -> 0.045108795 | I27: Formula
A28: BALANCE SHEET
B29: Cash & Cash Equivalents | C29: VND bn | D29: 4142.0158 | E29: =IFERROR('91_Raw_BS_vnstock'!F4/1000000000,0) -> 5061.0205 | F29: =IFERROR('91_Raw_BS_vnstock'!E4/1000000000,0) -> 5365.7049 | G29: =IFERROR('91_Raw_BS_vnstock'!D4/1000000000,0) -> 4897.3315 | H29: =IFERROR('91_Raw_BS_vnstock'!C4/1000000000,0) -> 4999.9257 | I29: 91_Raw_BS_vnstock | J29: cash_and_cash_equivalents
B30: Short-term Financial Investments | C30: VND bn | D30: 14236.626 | E30: =IFERROR('91_Raw_BS_vnstock'!F7/1000000000,0) -> 10069.25 | F30: =IFERROR('91_Raw_BS_vnstock'!E7/1000000000,0) -> 18937.008 | G30: =IFERROR('91_Raw_BS_vnstock'!D7/1000000000,0) -> 29324.442 | H30: =IFERROR('91_Raw_BS_vnstock'!C7/1000000000,0) -> 33874.27 | I30: 91_Raw_BS_vnstock | J30: short_term_financial_investments
B31: Receivables | C31: VND bn | D31: 3162.122 | E31: =IFERROR('91_Raw_BS_vnstock'!F14/1000000000,0) -> 3000.8175 | F31: =IFERROR('91_Raw_BS_vnstock'!E14/1000000000,0) -> 5158.8533 | G31: =IFERROR('91_Raw_BS_vnstock'!D14/1000000000,0) -> 8825.8962 | H31: =IFERROR('91_Raw_BS_vnstock'!C14/1000000000,0) -> 10182.836 | I31: 91_Raw_BS_vnstock | J31: short_term_receivables
B32: Inventory | C32: VND bn | D32: 29167.232 | E32: =IFERROR('91_Raw_BS_vnstock'!F23/1000000000,0) -> 25696.078 | F32: =IFERROR('91_Raw_BS_vnstock'!E23/1000000000,0) -> 21824.236 | G32: =IFERROR('91_Raw_BS_vnstock'!D23/1000000000,0) -> 22244.676 | H32: =IFERROR('91_Raw_BS_vnstock'!C23/1000000000,0) -> 27266.852 | I32: 91_Raw_BS_vnstock | J32: inventories
B33: Other Current Assets | C33: VND bn | D33: 1247.2614 | E33: =IFERROR('91_Raw_BS_vnstock'!F30/1000000000,0) -> 750.44187 | F33: =IFERROR('91_Raw_BS_vnstock'!E30/1000000000,0) -> 664.53608 | G33: =IFERROR('91_Raw_BS_vnstock'!D30/1000000000,0) -> 544.07677 | H33: =IFERROR('91_Raw_BS_vnstock'!C30/1000000000,0) -> 877.76701 | I33: 91_Raw_BS_vnstock | J33: other_short_term_assets
B34: Total Current Assets | C34: VND bn | D34: 51955.258 | E34: =IFERROR('91_Raw_BS_vnstock'!F3/1000000000,0) -> 44577.607 | F34: =IFERROR('91_Raw_BS_vnstock'!E3/1000000000,0) -> 51950.338 | G34: =IFERROR('91_Raw_BS_vnstock'!D3/1000000000,0) -> 65836.423 | H34: =IFERROR('91_Raw_BS_vnstock'!C3/1000000000,0) -> 77201.651 | I34: 91_Raw_BS_vnstock | J34: current_assets
B35: Fixed Assets | C35: VND bn | D35: 9647.1689 | E35: =IFERROR('91_Raw_BS_vnstock'!F45/1000000000,0) -> 9727.5029 | F35: =IFERROR('91_Raw_BS_vnstock'!E45/1000000000,0) -> 6500.1356 | G35: =IFERROR('91_Raw_BS_vnstock'!D45/1000000000,0) -> 3586.6287 | H35: =IFERROR('91_Raw_BS_vnstock'!C45/1000000000,0) -> 2598.1892 | I35: 91_Raw_BS_vnstock | J35: fixed_assets
B36: Long-term Financial Investments | C36: VND bn | D36: 0 | E36: =IFERROR('91_Raw_BS_vnstock'!F70/1000000000,0) -> 231.03484 | F36: =IFERROR('91_Raw_BS_vnstock'!E70/1000000000,0) -> 746.63225 | G36: =IFERROR('91_Raw_BS_vnstock'!D70/1000000000,0) -> 242.0358 | H36: =IFERROR('91_Raw_BS_vnstock'!C70/1000000000,0) -> 3136.3156 | I36: 91_Raw_BS_vnstock | J36: long_term_financial_investments
B37: Other Long-term Assets | C37: VND bn | D37: 806.89105 | E37: =IFERROR('91_Raw_BS_vnstock'!F78/1000000000,0) -> 670.59008 | F37: =IFERROR('91_Raw_BS_vnstock'!E78/1000000000,0) -> 452.06753 | G37: =IFERROR('91_Raw_BS_vnstock'!D78/1000000000,0) -> 358.45441 | H37: =IFERROR('91_Raw_BS_vnstock'!C78/1000000000,0) -> 514.74079 | I37: 91_Raw_BS_vnstock | J37: other_long_term_assets
B38: Total Assets | C38: VND bn | D38: 62971.405 | E38: =IFERROR('91_Raw_BS_vnstock'!F85/1000000000,0) -> 55834.096 | F38: =IFERROR('91_Raw_BS_vnstock'!E85/1000000000,0) -> 60111.237 | G38: =IFERROR('91_Raw_BS_vnstock'!D85/1000000000,0) -> 70437.776 | H38: =IFERROR('91_Raw_BS_vnstock'!C85/1000000000,0) -> 83945.62 | I38: 91_Raw_BS_vnstock | J38: total_assets
B39: Trade Payables | C39: VND bn | D39: 12179.775 | E39: =IFERROR('91_Raw_BS_vnstock'!F89/1000000000,0) -> 8745.8273 | F39: =IFERROR('91_Raw_BS_vnstock'!E89/1000000000,0) -> 7927.0697 | G39: =IFERROR('91_Raw_BS_vnstock'!D89/1000000000,0) -> 9179.6361 | H39: =IFERROR('91_Raw_BS_vnstock'!C89/1000000000,0) -> 13113.9 | I39: 91_Raw_BS_vnstock | J39: short_term_trade_accounts_payable
B40: Short-term Debt | C40: VND bn | D40: 24647.474 | E40: =IFERROR('91_Raw_BS_vnstock'!F99/1000000000,0) -> 10688.139 | F40: =IFERROR('91_Raw_BS_vnstock'!E99/1000000000,0) -> 19128.542 | G40: =IFERROR('91_Raw_BS_vnstock'!D99/1000000000,0) -> 27300.247 | H40: =IFERROR('91_Raw_BS_vnstock'!C99/1000000000,0) -> 29930.943 | I40: 91_Raw_BS_vnstock | J40: short_term_borrowings_and_financial_leases
B41: Current Liabilities | C41: VND bn | D41: 42593.159 | E41: =IFERROR('91_Raw_BS_vnstock'!F88/1000000000,0) -> 26000.264 | F41: =IFERROR('91_Raw_BS_vnstock'!E88/1000000000,0) -> 30765.261 | G41: =IFERROR('91_Raw_BS_vnstock'!D88/1000000000,0) -> 42316.199 | H41: =IFERROR('91_Raw_BS_vnstock'!C88/1000000000,0) -> 50769.502 | I41: 91_Raw_BS_vnstock | J41: current_liabilities
...

Sheet 04_Q1_Historical_FS
A1: MWG - Q1 Historical Financial Statements and LTM Bridge
A2: Unit: VND bn; Green = workbook link ; Black = formula ;LTM Mar-26 = FY2025 - Q1 2025 + Q1 2026 for flow items.
E3: 100_Raw_Peer_Metrics!A1
A4: Section | B4: Line Item | C4: Unit | D4: Q1 2025A | E4: Q1 2026A | F4: YoY / Change | G4: LTM Mar-26 / Q1 BS | H4: Source
A5: INCOME STATEMENT
B6: Gross Revenue | C6: VND bn | D6: =IFERROR('93_Raw_IS_Q_BCTC'!C4/1000000000,0) -> 36332.913 | E6: =IFERROR('93_Raw_IS_Q_BCTC'!D4/1000000000,0) -> 46709.163 | F6: =IFERROR(E6/D6-1,"") -> 0.28558816 | G6: ='03_Historical_FS'!H6-D6+E6 -> 167212.36 | H6: 93_Raw_IS_Q_BCTC:gross_revenue
B7: Revenue | C7: VND bn | D7: =IFERROR('93_Raw_IS_Q_BCTC'!C6/1000000000,0) -> 36134.958 | E7: =IFERROR('93_Raw_IS_Q_BCTC'!D6/1000000000,0) -> 46461.952 | F7: =IFERROR(E7/D7-1,"") -> 0.28578955 | G7: ='03_Historical_FS'!H7-D7+E7 -> 166255.14 | H7: Raw_IS_Q_vnstock:revenue
B8: COGS | C8: VND bn | D8: =IFERROR('93_Raw_IS_Q_BCTC'!C7/1000000000,0) -> 28934.548 | E8: =IFERROR('93_Raw_IS_Q_BCTC'!D7/1000000000,0) -> 36751.851 | F8: =IFERROR(E8/D8-1,"") -> 0.27017194 | G8: ='03_Historical_FS'!H8-D8+E8 -> 132743.57 | H8: Raw_IS_Q_vnstock:cogs
B9: Gross Profit | C9: VND bn | D9: =IFERROR('93_Raw_IS_Q_BCTC'!C8/1000000000,0) -> 7200.4106 | E9: =IFERROR('93_Raw_IS_Q_BCTC'!D8/1000000000,0) -> 9710.1014 | F9: =IFERROR(E9/D9-1,"") -> 0.34854829 | G9: ='03_Historical_FS'!H9-D9+E9 -> 33511.568 | H9: Raw_IS_Q_vnstock:gross_profit
B10: Gross Margin | C10: % | D10: =IFERROR(D9/D7,"") -> 0.19926439 | E10: =IFERROR(E9/E7,"") -> 0.20899039 | F10: =IFERROR(E10-D10,"") -> 0.0097259946 | G10: =IFERROR(G9/G7,"") -> 0.20156711 | H10: Formula
B11: Financial Income | C11: VND bn | D11: =IFERROR('93_Raw_IS_Q_BCTC'!C9/1000000000,0) -> 693.29367 | E11: =IFERROR('93_Raw_IS_Q_BCTC'!D9/1000000000,0) -> 857.86659 | F11: =IFERROR(E11/D11-1,"") -> 0.23737837 | G11: ='03_Historical_FS'!H11-D11+E11 -> 3271.9217 | H11: Raw_IS_Q_vnstock:financial_income
B12: Finance Expenses | C12: VND bn | D12: =IFERROR('93_Raw_IS_Q_BCTC'!C10/1000000000,0) -> 339.02316 | E12: =IFERROR('93_Raw_IS_Q_BCTC'!D10/1000000000,0) -> 421.76736 | F12: =IFERROR(E12/D12-1,"") -> 0.2440665 | G12: ='03_Historical_FS'!H12-D12+E12 -> 1625.2629 | H12: Raw_IS_Q_vnstock:finance_expenses
B13: Interest Expense | C13: VND bn | D13: =IFERROR('93_Raw_IS_Q_BCTC'!C11/1000000000,0) -> 322.79285 | E13: =IFERROR('93_Raw_IS_Q_BCTC'!D11/1000000000,0) -> 415.4489 | F13: =IFERROR(E13/D13-1,"") -> 0.28704494 | G13: ='03_Historical_FS'!H13-D13+E13 -> 1563.3316 | H13: Raw_IS_Q_vnstock:interest_expense
B14: Selling Expenses | C14: VND bn | D14: =IFERROR('93_Raw_IS_Q_BCTC'!C13/1000000000,0) -> 4403.0063 | E14: =IFERROR('93_Raw_IS_Q_BCTC'!D13/1000000000,0) -> 5284.9089 | F14: =IFERROR(E14/D14-1,"") -> 0.20029554 | G14: ='03_Historical_FS'!H14-D14+E14 -> 20212.806 | H14: Raw_IS_Q_vnstock:selling_expenses
B15: G&A Expenses | C15: VND bn | D15: =IFERROR('93_Raw_IS_Q_BCTC'!C14/1000000000,0) -> 1214.5998 | E15: =IFERROR('93_Raw_IS_Q_BCTC'!D14/1000000000,0) -> 1523.1801 | F15: =IFERROR(E15/D15-1,"") -> 0.25405926 | G15: ='03_Historical_FS'!H15-D15+E15 -> 4904.6548 | H15: Raw_IS_Q_vnstock:admin_expenses
B16: Operating Expenses | C16: VND bn | D16: =D14+D15 -> 5617.6061 | E16: =E14+E15 -> 6808.089 | F16: =IFERROR(E16/D16-1,"") -> 0.21191996 | G16: =G14+G15 -> 25117.461 | H16: Formula
B17: EBIT | C17: VND bn | D17: =IFERROR('93_Raw_IS_Q_BCTC'!C15/1000000000,0) -> 1940.2048 | E17: =IFERROR('93_Raw_IS_Q_BCTC'!D15/1000000000,0) -> 3347.1234 | F17: =IFERROR(E17/D17-1,"") -> 0.72513926 | G17: ='03_Historical_FS'!H17-D17+E17 -> 10070.999 | H17: Raw_IS_Q_vnstock:ebit
B18: EBIT Margin | C18: % | D18: =IFERROR(D17/D7,"") -> 0.053693289 | E18: =IFERROR(E17/E7,"") -> 0.072040095 | F18: =IFERROR(E18-D18,"") -> 0.018346806 | G18: =IFERROR(G17/G7,"") -> 0.060575566 | H18: Formula
B19: Other Profit | C19: VND bn | D19: =IFERROR('93_Raw_IS_Q_BCTC'!C18/1000000000,0) -> -5.5433771 | E19: =IFERROR('93_Raw_IS_Q_BCTC'!D18/1000000000,0) -> -19.539118 | F19: =IFERROR(E19/D19-1,"") -> 2.5247679 | G19: ='03_Historical_FS'!H19-D19+E19 -> -45.008647 | H19: Raw_IS_Q_vnstock:other_profit
B20: Profit Before Tax | C20: VND bn | D20: =IFERROR('93_Raw_IS_Q_BCTC'!C19/1000000000,0) -> 1934.6614 | E20: =IFERROR('93_Raw_IS_Q_BCTC'!D19/1000000000,0) -> 3327.5843 | F20: =IFERROR(E20/D20-1,"") -> 0.71998279 | G20: ='03_Historical_FS'!H20-D20+E20 -> 10025.99 | H20: Raw_IS_Q_vnstock:pbt
B21: Current Tax Expense | C21: VND bn | D21: =IFERROR('93_Raw_IS_Q_BCTC'!C20/1000000000,0) -> 397.72242 | E21: =IFERROR('93_Raw_IS_Q_BCTC'!D20/1000000000,0) -> 797.0122 | F21: =IFERROR(E21/D21-1,"") -> 1.0039409 | G21: ='03_Historical_FS'!H21-D21+E21 -> 2120.8493 | H21: Raw_IS_Q_vnstock:current_tax
B22: Deferred Tax Expense | C22: VND bn | D22: =IFERROR('93_Raw_IS_Q_BCTC'!C21/1000000000,0) -> -10.894797 | E22: =IFERROR('93_Raw_IS_Q_BCTC'!D21/1000000000,0) -> -226.98492 | F22: =IFERROR(E22/D22-1,"") -> 19.83425 | G22: ='03_Historical_FS'!H22-D22+E22 -> -377.20495 | H22: Raw_IS_Q_vnstock:deferred_tax
B23: Total Tax Expense | C23: VND bn | D23: =IFERROR('93_Raw_IS_Q_BCTC'!C22/1000000000,0) -> 386.82762 | E23: =IFERROR('93_Raw_IS_Q_BCTC'!D22/1000000000,0) -> 570.02728 | F23: =IFERROR(E23/D23-1,"") -> 0.47359509 | G23: ='03_Historical_FS'!H23-D23+E23 -> 1743.6444 | H23: Raw_IS_Q_vnstock:total_tax
B24: NPAT | C24: VND bn | D24: =IFERROR('93_Raw_IS_Q_BCTC'!C23/1000000000,0) -> 1547.8338 | E24: =IFERROR('93_Raw_IS_Q_BCTC'!D23/1000000000,0) -> 2757.557 | F24: =IFERROR(E24/D24-1,"") -> 0.7815589 | G24: ='03_Historical_FS'!H24-D24+E24 -> 8282.3461 | H24: Raw_IS_Q_vnstock:npat
B25: Minority Interest - IS | C25: VND bn | D25: =IFERROR('93_Raw_IS_Q_BCTC'!C24/1000000000,0) -> 1.8966777 | E25: =IFERROR('93_Raw_IS_Q_BCTC'!D24/1000000000,0) -> 43.126168 | F25: =IFERROR(E25/D25-1,"") -> 21.737742 | G25: ='03_Historical_FS'!H25-D25+E25 -> 80.121607 | H25: Raw_IS_Q_vnstock:minority_interest_is
B26: NPATMI | C26: VND bn | D26: =IFERROR('93_Raw_IS_Q_BCTC'!C25/1000000000,0) -> 1545.9371 | E26: =IFERROR('93_Raw_IS_Q_BCTC'!D25/1000000000,0) -> 2714.4309 | F26: =IFERROR(E26/D26-1,"") -> 0.7558482 | G26: ='03_Historical_FS'!H26-D26+E26 -> 8202.2245 | H26: Raw_IS_Q_vnstock:npatmi
B27: NPATMI Margin | C27: % | D27: =IFERROR(D26/D7,"") -> 0.042782313 | E27: =IFERROR(E26/E7,"") -> 0.058422661 | F27: =IFERROR(E27-D27,"") -> 0.015640348 | G27: =IFERROR(G26/G7,"") -> 0.049335164 | H27: Formula
A28: BALANCE SHEET
B29: Cash & Cash Equivalents | C29: VND bn | D29: =IFERROR('94_Raw_BS_Q_BCTC'!C5/1000000000,0) -> 2658.2181 | E29: =IFERROR('94_Raw_BS_Q_BCTC'!D5/1000000000,0) -> 4553.6526 | F29: =IFERROR(E29/D29-1,"") -> 0.71304699 | G29: =E29 -> 4553.6526 | H29: Raw_BS_Q_vnstock:cash
B30: Short-term Financial Investments | C30: VND bn | D30: =IFERROR('94_Raw_BS_Q_BCTC'!C6/1000000000,0) -> 32390.515 | E30: =IFERROR('94_Raw_BS_Q_BCTC'!D6/1000000000,0) -> 41831.154 | F30: =IFERROR(E30/D30-1,"") -> 0.29146306 | G30: =E30 -> 41831.154 | H30: Raw_BS_Q_vnstock:short_term_investments
B31: Receivables | C31: VND bn | D31: =IFERROR('94_Raw_BS_Q_BCTC'!C7/1000000000,0) -> 9862.5322 | E31: =IFERROR('94_Raw_BS_Q_BCTC'!D7/1000000000,0) -> 2121.016 | F31: =IFERROR(E31/D31-1,"") -> -0.78494205 | G31: =E31 -> 2121.016 | H31: Raw_BS_Q_vnstock:receivables
B32: Inventory | C32: VND bn | D32: =IFERROR('94_Raw_BS_Q_BCTC'!C8/1000000000,0) -> 22808.478 | E32: =IFERROR('94_Raw_BS_Q_BCTC'!D8/1000000000,0) -> 27600.708 | F32: =IFERROR(E32/D32-1,"") -> 0.21010738 | G32: =E32 -> 27600.708 | H32: Raw_BS_Q_vnstock:inventory
B33: Other Current Assets | C33: VND bn | D33: =IFERROR('94_Raw_BS_Q_BCTC'!C9/1000000000,0) -> 630.45865 | E33: =IFERROR('94_Raw_BS_Q_BCTC'!D9/1000000000,0) -> 728.08177 | F33: =IFERROR(E33/D33-1,"") -> 0.1548446 | G33: =E33 -> 728.08177 | H33: Raw_BS_Q_vnstock:other_current_assets
B34: Total Current Assets | C34: VND bn | D34: =IFERROR('94_Raw_BS_Q_BCTC'!C4/1000000000,0) -> 68350.202 | E34: =IFERROR('94_Raw_BS_Q_BCTC'!D4/1000000000,0) -> 76834.612 | F34: =IFERROR(E34/D34-1,"") -> 0.12413145 | G34: =E34 -> 76834.612 | H34: Raw_BS_Q_vnstock:current_assets
B35: Fixed Assets | C35: VND bn | D35: =IFERROR('94_Raw_BS_Q_BCTC'!C11/1000000000,0) -> 3233.9016 | E35: =IFERROR('94_Raw_BS_Q_BCTC'!D11/1000000000,0) -> 2418.4474 | F35: =IFERROR(E35/D35-1,"") -> -0.25215802 | G35: =E35 -> 2418.4474 | H35: Raw_BS_Q_vnstock:fixed_assets
B36: Long-term Financial Investments | C36: VND bn | D36: =IFERROR('94_Raw_BS_Q_BCTC'!C12/1000000000,0) -> 245.16557 | E36: =IFERROR('94_Raw_BS_Q_BCTC'!D12/1000000000,0) -> 3466.7225 | F36: =IFERROR(E36/D36-1,"") -> 13.140332 | G36: =E36 -> 3466.7225 | H36: Raw_BS_Q_vnstock:long_term_investments
B37: Other Long-term Assets | C37: VND bn | D37: =IFERROR('94_Raw_BS_Q_BCTC'!C13/1000000000,0) -> 395.22353 | E37: =IFERROR('94_Raw_BS_Q_BCTC'!D13/1000000000,0) -> 723.1644 | F37: =IFERROR(E37/D37-1,"") -> 0.82976047 | G37: =E37 -> 723.1644 | H37: Raw_BS_Q_vnstock:other_long_term_assets
B38: Total Assets | C38: VND bn | D38: =IFERROR('94_Raw_BS_Q_BCTC'!C14/1000000000,0) -> 72679.225 | E38: =IFERROR('94_Raw_BS_Q_BCTC'!D14/1000000000,0) -> 83994.558 | F38: =IFERROR(E38/D38-1,"") -> 0.1556887 | G38: =E38 -> 83994.558 | H38: Raw_BS_Q_vnstock:total_assets
B39: Trade Payables | C39: VND bn | D39: =IFERROR('94_Raw_BS_Q_BCTC'!C15/1000000000,0) -> 11308.959 | E39: =IFERROR('94_Raw_BS_Q_BCTC'!D15/1000000000,0) -> 11892.522 | F39: =IFERROR(E39/D39-1,"") -> 0.051601815 | G39: =E39 -> 11892.522 | H39: Raw_BS_Q_vnstock:trade_payables
B40: Short-term Debt | C40: VND bn | D40: =IFERROR('94_Raw_BS_Q_BCTC'!C16/1000000000,0) -> 26222.186 | E40: =IFERROR('94_Raw_BS_Q_BCTC'!D16/1000000000,0) -> 28100.653 | F40: =IFERROR(E40/D40-1,"") -> 0.071636558 | G40: =E40 -> 28100.653 | H40: Raw_BS_Q_vnstock:short_term_debt
...

Sheet 05_Ratio_Analysis
A1: MWG - Ratio Analysis
A4: Section | B4: Metric | C4: Unit | D4: 2021A | E4: 2022A | F4: 2023A | G4: 2024A | H4: 2025A | I4: Q1 2025A | J4: Q1 2026A | K4: LTM Mar-26 | M4: ROIC tax rate | N4: 0.2
A5: KEY DATA | M5: Q1 annualization factor | N5: 4
B6: Revenue | C6: VND bn | D6: =IFERROR('03_Historical_FS'!D7,"") -> 122958.11 | E6: =IFERROR('03_Historical_FS'!E7,"") -> 133404.78 | F6: =IFERROR('03_Historical_FS'!F7,"") -> 118279.79 | G6: =IFERROR('03_Historical_FS'!G7,"") -> 134341.15 | H6: =IFERROR('03_Historical_FS'!H7,"") -> 155928.15 | I6: =IFERROR('04_Q1_Historical_FS'!D7,"") -> 36134.958 | J6: =IFERROR('04_Q1_Historical_FS'!E7,"") -> 46461.952 | K6: =IFERROR('04_Q1_Historical_FS'!G7,"") -> 166255.14 | M6: Days per year | N6: 365
B7: NPATMI | C7: VND bn | D7: =IFERROR('03_Historical_FS'!D26,"") -> 4898.8693 | E7: =IFERROR('03_Historical_FS'!E26,"") -> 4099.763 | F7: =IFERROR('03_Historical_FS'!F26,"") -> 167.66939 | G7: =IFERROR('03_Historical_FS'!G26,"") -> 3721.8684 | H7: =IFERROR('03_Historical_FS'!H26,"") -> 7033.7308 | I7: =IFERROR('04_Q1_Historical_FS'!D26,"") -> 1545.9371 | J7: =IFERROR('04_Q1_Historical_FS'!E26,"") -> 2714.4309 | K7: =IFERROR('04_Q1_Historical_FS'!G26,"") -> 8202.2245 | M7: Q1 day factor | N7: =N6/N5 -> 91.25
B8: EBITDA | C8: VND bn | D8: =IFERROR('03_Historical_FS'!D69,"") -> 9386.3205 | E8: =IFERROR('03_Historical_FS'!E69,"") -> 10115.018 | F8: =IFERROR('03_Historical_FS'!F69,"") -> 4398.3826 | G8: =IFERROR('03_Historical_FS'!G69,"") -> 8140.4645 | H8: =IFERROR('03_Historical_FS'!H69,"") -> 10554.963 | I8: =IFERROR('04_Q1_Historical_FS'!D69,"") -> 2449.1242 | J8: =IFERROR('04_Q1_Historical_FS'!E69,"") -> 3741.0534 | K8: =IFERROR('04_Q1_Historical_FS'!G69,"") -> 11846.892
B9: EBIT | C9: VND bn | D9: =IFERROR('03_Historical_FS'!D17,"") -> 6465.6069 | E9: =IFERROR('03_Historical_FS'!E17,"") -> 6574.6937 | F9: =IFERROR('03_Historical_FS'!F17,"") -> 1047.0684 | G9: =IFERROR('03_Historical_FS'!G17,"") -> 5227.0454 | H9: =IFERROR('03_Historical_FS'!H17,"") -> 8664.0805 | I9: =IFERROR('04_Q1_Historical_FS'!D17,"") -> 1940.2048 | J9: =IFERROR('04_Q1_Historical_FS'!E17,"") -> 3347.1234 | K9: =IFERROR('04_Q1_Historical_FS'!G17,"") -> 10070.999
B10: Interest Expense | C10: VND bn | D10: =IFERROR('03_Historical_FS'!D13,"") -> 674.42775 | E10: =IFERROR('03_Historical_FS'!E13,"") -> 1362.1439 | F10: =IFERROR('03_Historical_FS'!F13,"") -> 1447.7184 | G10: =IFERROR('03_Historical_FS'!G13,"") -> 1137.2361 | H10: =IFERROR('03_Historical_FS'!H13,"") -> 1470.6756 | I10: =IFERROR('04_Q1_Historical_FS'!D13,"") -> 322.79285 | J10: =IFERROR('04_Q1_Historical_FS'!E13,"") -> 415.4489 | K10: =IFERROR('04_Q1_Historical_FS'!G13,"") -> 1563.3316
B11: Net Debt | C11: VND bn | D11: =IFERROR('03_Historical_FS'!D51,"") -> 6268.8322 | E11: =IFERROR('03_Historical_FS'!E51,"") -> 1459.1185 | F11: =IFERROR('03_Historical_FS'!F51,"") -> 811.07889 | G11: =IFERROR('03_Historical_FS'!G51,"") -> -6921.5266 | H11: =IFERROR('03_Historical_FS'!H51,"") -> -8943.2529 | I11: =IFERROR('04_Q1_Historical_FS'!D51,"") -> -8826.5471 | J11: =IFERROR('04_Q1_Historical_FS'!E51,"") -> -18284.153 | K11: =IFERROR('04_Q1_Historical_FS'!G51,"") -> -18284.153
B12: Cash + ST Investments | C12: VND bn | D12: =IFERROR('03_Historical_FS'!D29+'03_Historical_FS'!D30,"") -> 18378.642 | E12: =IFERROR('03_Historical_FS'!E29+'03_Historical_FS'!E30,"") -> 15130.27 | F12: =IFERROR('03_Historical_FS'!F29+'03_Historical_FS'!F30,"") -> 24302.713 | G12: =IFERROR('03_Historical_FS'!G29+'03_Historical_FS'!G30,"") -> 34221.773 | H12: =IFERROR('03_Historical_FS'!H29+'03_Historical_FS'!H30,"") -> 38874.196 | I12: =IFERROR('04_Q1_Historical_FS'!D29+'04_Q1_Historical_FS'!D30,"") -> 35048.733 | J12: =IFERROR('04_Q1_Historical_FS'!E29+'04_Q1_Historical_FS'!E30,"") -> 46384.806 | K12: =IFERROR('04_Q1_Historical_FS'!G29+'04_Q1_Historical_FS'!G30,"") -> 46384.806
A13: PROFITABILITY
B14: Gross Margin | C14: % | D14: =IFERROR('03_Historical_FS'!D10,"") -> 0.22472802 | E14: =IFERROR('03_Historical_FS'!E10,"") -> 0.23134136 | F14: =IFERROR('03_Historical_FS'!F10,"") -> 0.1904012 | G14: =IFERROR('03_Historical_FS'!G10,"") -> 0.20469684 | H14: =IFERROR('03_Historical_FS'!H10,"") -> 0.19882156 | I14: =IFERROR('04_Q1_Historical_FS'!D10,"") -> 0.19926439 | J14: =IFERROR('04_Q1_Historical_FS'!E10,"") -> 0.20899039 | K14: =IFERROR('04_Q1_Historical_FS'!G10,"") -> 0.20156711
B15: EBIT Margin | C15: % | D15: =IFERROR('03_Historical_FS'!D18,"") -> 0.05258382 | E15: =IFERROR('03_Historical_FS'!E18,"") -> 0.049283795 | F15: =IFERROR('03_Historical_FS'!F18,"") -> 0.0088524706 | G15: =IFERROR('03_Historical_FS'!G18,"") -> 0.038908743 | H15: =IFERROR('03_Historical_FS'!H18,"") -> 0.055564571 | I15: =IFERROR('04_Q1_Historical_FS'!D18,"") -> 0.053693289 | J15: =IFERROR('04_Q1_Historical_FS'!E18,"") -> 0.072040095 | K15: =IFERROR('04_Q1_Historical_FS'!G18,"") -> 0.060575566
B16: NPATMI Margin | C16: % | D16: =IFERROR('03_Historical_FS'!D27,"") -> 0.039841776 | E16: =IFERROR('03_Historical_FS'!E27,"") -> 0.030731756 | F16: =IFERROR('03_Historical_FS'!F27,"") -> 0.0014175659 | G16: =IFERROR('03_Historical_FS'!G27,"") -> 0.027704604 | H16: =IFERROR('03_Historical_FS'!H27,"") -> 0.045108795 | I16: =IFERROR('04_Q1_Historical_FS'!D27,"") -> 0.042782313 | J16: =IFERROR('04_Q1_Historical_FS'!E27,"") -> 0.058422661 | K16: =IFERROR('04_Q1_Historical_FS'!G27,"") -> 0.049335164
B17: ROE | C17: % | D17: =IFERROR('03_Historical_FS'!D26/'03_Historical_FS'!D48,"") -> 0.240397 | E17: =IFERROR('03_Historical_FS'!E26/AVERAGE('03_Historical_FS'!D48,'03_Historical_FS'!E48),"") -> 0.18504565 | F17: =IFERROR('03_Historical_FS'!F26/AVERAGE('03_Historical_FS'!E48,'03_Historical_FS'!F48),"") -> 0.0070907933 | G17: =IFERROR('03_Historical_FS'!G26/AVERAGE('03_Historical_FS'!F48,'03_Historical_FS'!G48),"") -> 0.14459155 | H17: =IFERROR('03_Historical_FS'!H26/AVERAGE('03_Historical_FS'!G48,'03_Historical_FS'!H48),"") -> 0.22949414 | I17: =IFERROR(('04_Q1_Historical_FS'!D26*$N$5)/AVERAGE('03_Historical_FS'!G48,'04_Q1_Historical_FS'!D48),"") -> 0.21400493 | J17: =IFERROR(('04_Q1_Historical_FS'!E26*$N$5)/AVERAGE('03_Historical_FS'!H48,'04_Q1_Historical_FS'!E48),"") -> 0.31421815 | K17: =IFERROR('04_Q1_Historical_FS'!G26/AVERAGE('03_Historical_FS'!H48,'04_Q1_Historical_FS'!E48),"") -> 0.23736908
B18: ROA | C18: % | D18: =IFERROR('03_Historical_FS'!D24/'03_Historical_FS'!D38,"") -> 0.077835752 | E18: =IFERROR('03_Historical_FS'!E24/AVERAGE('03_Historical_FS'!D38,'03_Historical_FS'!E38),"") -> 0.069049234 | F18: =IFERROR('03_Historical_FS'!F24/AVERAGE('03_Historical_FS'!E38,'03_Historical_FS'!F38),"") -> 0.0028949704 | G18: =IFERROR('03_Historical_FS'!G24/AVERAGE('03_Historical_FS'!F38,'03_Historical_FS'!G38),"") -> 0.057193665 | H18: =IFERROR('03_Historical_FS'!H24/AVERAGE('03_Historical_FS'!G38,'03_Historical_FS'!H38),"") -> 0.09162414 | I18: =IFERROR(('04_Q1_Historical_FS'!D24*$N$5)/AVERAGE('03_Historical_FS'!G38,'04_Q1_Historical_FS'!D38),"") -> 0.086521309 | J18: =IFERROR(('04_Q1_Historical_FS'!E24*$N$5)/AVERAGE('03_Historical_FS'!H38,'04_Q1_Historical_FS'!E38),"") -> 0.13135901 | K18: =IFERROR('04_Q1_Historical_FS'!G24/AVERAGE('03_Historical_FS'!H38,'04_Q1_Historical_FS'!E38),"") -> 0.098634481
B19: ROIC | C19: % | D19: =IFERROR(('03_Historical_FS'!D17*(1-$N$4))/('03_Historical_FS'!D50+'03_Historical_FS'!D48-'03_Historical_FS'!D29-'03_Historical_FS'!D30),"") -> 0.1941108 | E19: =IFERROR(('03_Historical_FS'!E17*(1-$N$4))/AVERAGE(('03_Historical_FS'!D50+'03_Historical_FS'!D48-'03_Historical_FS'!D29-'03_Historical_FS'!D30),('03_Historical_FS'!E50+'03_Historical_FS'!E48-'03_Historical_FS'!E29-'03_Historical_FS'!E30)),"") -> 0.20214752 | F19: =IFERROR(('03_Historical_FS'!F17*(1-$N$4))/AVERAGE(('03_Historical_FS'!E50+'03_Historical_FS'!E48-'03_Historical_FS'!E29-'03_Historical_FS'!E30),('03_Historical_FS'!F50+'03_Historical_FS'!F48-'03_Historical_FS'!F29-'03_Historical_FS'!F30)),"") -> 0.033802066 | G19: =IFERROR(('03_Historical_FS'!G17*(1-$N$4))/AVERAGE(('03_Historical_FS'!F50+'03_Historical_FS'!F48-'03_Historical_FS'!F29-'03_Historical_FS'!F30),('03_Historical_FS'!G50+'03_Historical_FS'!G48-'03_Historical_FS'!G29-'03_Historical_FS'!G30)),"") -> 0.18433207 | H19: =IFERROR(('03_Historical_FS'!H17*(1-$N$4))/AVERAGE(('03_Historical_FS'!G50+'03_Historical_FS'!G48-'03_Historical_FS'!G29-'03_Historical_FS'!G30),('03_Historical_FS'!H50+'03_Historical_FS'!H48-'03_Historical_FS'!H29-'03_Historical_FS'!H30)),"") -> 0.30512083 | I19: =IFERROR((('04_Q1_Historical_FS'!D17*$N$5)*(1-$N$4))/AVERAGE(('03_Historical_FS'!G50+'03_Historical_FS'!G48-'03_Historical_FS'!G29-'03_Historical_FS'!G30),('04_Q1_Historical_FS'!D50+'04_Q1_Historical_FS'!D48-'04_Q1_Historical_FS'!D29-'04_Q1_Historical_FS'!D30)),"") -> 0.29535042 | J19: =IFERROR((('04_Q1_Historical_FS'!E17*$N$5)*(1-$N$4))/AVERAGE(('03_Historical_FS'!H50+'03_Historical_FS'!H48-'03_Historical_FS'!H29-'03_Historical_FS'!H30),('04_Q1_Historical_FS'!E50+'04_Q1_Historical_FS'!E48-'04_Q1_Historical_FS'!E29-'04_Q1_Historical_FS'!E30)),"") -> 0.5114742 | K19: =IFERROR(('04_Q1_Historical_FS'!G17*(1-$N$4))/AVERAGE(('03_Historical_FS'!H50+'03_Historical_FS'!H48-'03_Historical_FS'!H29-'03_Historical_FS'!H30),('04_Q1_Historical_FS'!E50+'04_Q1_Historical_FS'!E48-'04_Q1_Historical_FS'!E29-'04_Q1_Historical_FS'!E30)),"") -> 0.38473755
A20: WORKING CAPITAL
B21: Inventory Days | C21: days | D21: =IFERROR('03_Historical_FS'!D32/'03_Historical_FS'!D8*$N$6,"") -> 111.68037 | E21: =IFERROR(AVERAGE('03_Historical_FS'!D32,'03_Historical_FS'!E32)/'03_Historical_FS'!E8*$N$6,"") -> 97.642744 | F21: =IFERROR(AVERAGE('03_Historical_FS'!E32,'03_Historical_FS'!F32)/'03_Historical_FS'!F8*$N$6,"") -> 90.565287 | G21: =IFERROR(AVERAGE('03_Historical_FS'!F32,'03_Historical_FS'!G32)/'03_Historical_FS'!G8*$N$6,"") -> 75.27546 | H21: =IFERROR(AVERAGE('03_Historical_FS'!G32,'03_Historical_FS'!H32)/'03_Historical_FS'!H8*$N$6,"") -> 72.329495 | I21: =IFERROR(AVERAGE('03_Historical_FS'!G32,'04_Q1_Historical_FS'!D32)/('04_Q1_Historical_FS'!D8*$N$5)*$N$6,"") -> 71.041379 | J21: =IFERROR(AVERAGE('03_Historical_FS'!H32,'04_Q1_Historical_FS'!E32)/('04_Q1_Historical_FS'!E8*$N$5)*$N$6,"") -> 68.114459 | K21: =IFERROR(AVERAGE('03_Historical_FS'!H32,'04_Q1_Historical_FS'!E32)/'04_Q1_Historical_FS'!G8*$N$6,"") -> 75.433632
B22: Receivable Days | C22: days | D22: =IFERROR('03_Historical_FS'!D31/'03_Historical_FS'!D7*$N$6,"") -> 9.3867298 | E22: =IFERROR(AVERAGE('03_Historical_FS'!D31,'03_Historical_FS'!E31)/'03_Historical_FS'!E7*$N$6,"") -> 8.4310058 | F22: =IFERROR(AVERAGE('03_Historical_FS'!E31,'03_Historical_FS'!F31)/'03_Historical_FS'!F7*$N$6,"") -> 12.589978 | G22: =IFERROR(AVERAGE('03_Historical_FS'!F31,'03_Historical_FS'!G31)/'03_Historical_FS'!G7*$N$6,"") -> 18.998027 | H22: =IFERROR(AVERAGE('03_Historical_FS'!G31,'03_Historical_FS'!H31)/'03_Historical_FS'!H7*$N$6,"") -> 22.248027 | I22: =IFERROR(AVERAGE('03_Historical_FS'!G31,'04_Q1_Historical_FS'!D31)/('04_Q1_Historical_FS'!D7*$N$5)*$N$6,"") -> 23.596528 | J22: =IFERROR(AVERAGE('03_Historical_FS'!H31,'04_Q1_Historical_FS'!E31)/('04_Q1_Historical_FS'!E7*$N$5)*$N$6,"") -> 12.082214 | K22: =IFERROR(AVERAGE('03_Historical_FS'!H31,'04_Q1_Historical_FS'!E31)/'04_Q1_Historical_FS'!G7*$N$6,"") -> 13.506067
B23: Payable Days | C23: days | D23: =IFERROR('03_Historical_FS'!D39/'03_Historical_FS'!D8*$N$6,"") -> 46.635955 | E23: =IFERROR(AVERAGE('03_Historical_FS'!D39,'03_Historical_FS'!E39)/'03_Historical_FS'!E8*$N$6,"") -> 37.242252 | F23: =IFERROR(AVERAGE('03_Historical_FS'!E39,'03_Historical_FS'!F39)/'03_Historical_FS'!F8*$N$6,"") -> 31.775584 | G23: =IFERROR(AVERAGE('03_Historical_FS'!F39,'03_Historical_FS'!G39)/'03_Historical_FS'!G8*$N$6,"") -> 29.220489 | H23: =IFERROR(AVERAGE('03_Historical_FS'!G39,'03_Historical_FS'!H39)/'03_Historical_FS'!H8*$N$6,"") -> 32.567772 | I23: =IFERROR(AVERAGE('03_Historical_FS'!G39,'04_Q1_Historical_FS'!D39)/('04_Q1_Historical_FS'!D8*$N$5)*$N$6,"") -> 32.307128 | J23: =IFERROR(AVERAGE('03_Historical_FS'!H39,'04_Q1_Historical_FS'!E39)/('04_Q1_Historical_FS'!E8*$N$5)*$N$6,"") -> 31.043824 | K23: =IFERROR(AVERAGE('03_Historical_FS'!H39,'04_Q1_Historical_FS'!E39)/'04_Q1_Historical_FS'!G8*$N$6,"") -> 34.379608
B24: Cash Conversion Cycle | C24: days | D24: =IFERROR(D21+D22-D23,"") -> 74.431142 | E24: =IFERROR(E21+E22-E23,"") -> 68.831498 | F24: =IFERROR(F21+F22-F23,"") -> 71.379681 | G24: =IFERROR(G21+G22-G23,"") -> 65.052998 | H24: =IFERROR(H21+H22-H23,"") -> 62.00975 | I24: =IFERROR(I21+I22-I23,"") -> 62.330779 | J24: =IFERROR(J21+J22-J23,"") -> 49.152849 | K24: =IFERROR(K21+K22-K23,"") -> 54.560091
A25: LEVERAGE / LIQUIDITY
B26: Current Ratio | C26: x | D26: =IFERROR('03_Historical_FS'!D34/'03_Historical_FS'!D41,"") -> 1.2198029 | E26: =IFERROR('03_Historical_FS'!E34/'03_Historical_FS'!E41,"") -> 1.7145059 | F26: =IFERROR('03_Historical_FS'!F34/'03_Historical_FS'!F41,"") -> 1.6886039 | G26: =IFERROR('03_Historical_FS'!G34/'03_Historical_FS'!G41,"") -> 1.5558208 | H26: =IFERROR('03_Historical_FS'!H34/'03_Historical_FS'!H41,"") -> 1.5206304 | I26: =IFERROR('04_Q1_Historical_FS'!D34/'04_Q1_Historical_FS'!D41,"") -> 1.5891666 | J26: =IFERROR('04_Q1_Historical_FS'!E34/'04_Q1_Historical_FS'!E41,"") -> 1.5986822 | K26: =IFERROR('04_Q1_Historical_FS'!G34/'04_Q1_Historical_FS'!G41,"") -> 1.5986822
B27: Quick Ratio | C27: x | D27: =IFERROR(('03_Historical_FS'!D29+'03_Historical_FS'!D30+'03_Historical_FS'!D31)/'03_Historical_FS'!D41,"") -> 0.50573295 | E27: =IFERROR(('03_Historical_FS'!E29+'03_Historical_FS'!E30+'03_Historical_FS'!E31)/'03_Historical_FS'!E41,"") -> 0.69734244 | F27: =IFERROR(('03_Historical_FS'!F29+'03_Historical_FS'!F30+'03_Historical_FS'!F31)/'03_Historical_FS'!F41,"") -> 0.95762447 | G27: =IFERROR(('03_Historical_FS'!G29+'03_Historical_FS'!G30+'03_Historical_FS'!G31)/'03_Historical_FS'!G41,"") -> 1.0172858 | H27: =IFERROR(('03_Historical_FS'!H29+'03_Historical_FS'!H30+'03_Historical_FS'!H31)/'03_Historical_FS'!H41,"") -> 0.9662697 | I27: =IFERROR(('04_Q1_Historical_FS'!D29+'04_Q1_Historical_FS'!D30+'04_Q1_Historical_FS'!D31)/'04_Q1_Historical_FS'!D41,"") -> 1.044203 | J27: =IFERROR(('04_Q1_Historical_FS'!E29+'04_Q1_Historical_FS'!E30+'04_Q1_Historical_FS'!E31)/'04_Q1_Historical_FS'!E41,"") -> 1.0092508 | K27: =IFERROR(('04_Q1_Historical_FS'!G29+'04_Q1_Historical_FS'!G30+'04_Q1_Historical_FS'!G31)/'04_Q1_Historical_FS'!G41,"") -> 1.0092508
B28: Net Debt / EBITDA | C28: x | D28: =IFERROR('03_Historical_FS'!D51/'03_Historical_FS'!D69,"") -> 0.66786897 | E28: =IFERROR('03_Historical_FS'!E51/'03_Historical_FS'!E69,"") -> 0.14425268 | F28: =IFERROR('03_Historical_FS'!F51/'03_Historical_FS'!F69,"") -> 0.18440389 | G28: =IFERROR('03_Historical_FS'!G51/'03_Historical_FS'!G69,"") -> -0.85026187 | H28: =IFERROR('03_Historical_FS'!H51/'03_Historical_FS'!H69,"") -> -0.84730313 | I28: =IFERROR('04_Q1_Historical_FS'!D51/('04_Q1_Historical_FS'!D69*$N$5),"") -> -0.90099014 | J28: =IFERROR('04_Q1_Historical_FS'!E51/('04_Q1_Historical_FS'!E69*$N$5),"") -> -1.2218586 | K28: =IFERROR('04_Q1_Historical_FS'!G51/'04_Q1_Historical_FS'!G69,"") -> -1.5433713
B29: Interest Coverage | C29: x | D29: =IFERROR('03_Historical_FS'!D17/'03_Historical_FS'!D13,"") -> 9.5868044 | E29: =IFERROR('03_Historical_FS'!E17/'03_Historical_FS'!E13,"") -> 4.8267247 | F29: =IFERROR('03_Historical_FS'!F17/'03_Historical_FS'!F13,"") -> 0.72325418 | G29: =IFERROR('03_Historical_FS'!G17/'03_Historical_FS'!G13,"") -> 4.596271 | H29: =IFERROR('03_Historical_FS'!H17/'03_Historical_FS'!H13,"") -> 5.8912248 | I29: =IFERROR('04_Q1_Historical_FS'!D17/'04_Q1_Historical_FS'!D13,"") -> 6.0106807 | J29: =IFERROR('04_Q1_Historical_FS'!E17/'04_Q1_Historical_FS'!E13,"") -> 8.0566428 | K29: =IFERROR('04_Q1_Historical_FS'!G17/'04_Q1_Historical_FS'!G13,"") -> 6.4420107

Sheet 06_Revenue_Drivers_Hist
A1: MWG - 06_Revenue_Drivers_Hist
A2: Unit: VND bn unless otherwise stated | Blue = hardcoded input from source | Black = formula/calculation ;Green =Linked rawsource
A4: Section | B4: Line Item | C4: Unit | D4: 2021A | E4: 2022A | F4: 2023A | G4: 2024A | H4: 2025A | I4: 3M2026 | J4: 5M2026 | K4: 2021-25 CAGR / Avg | L4: 2026E Anchor
A5: GROUP SUMMARY
B6: Months represented | C6: months | D6: 12 | E6: 12 | F6: 12 | G6: 12 | H6: 12 | I6: 3 | J6: =IFERROR(INDEX('96_Raw_Phase4_Drivers'!$E$4:$G$180,MATCH("latest_months",'96_Raw_Phase4_Drivers'!$B$4:$B$180,0),MATCH("Base",'96_Raw_Phase4_Drivers'!$E$3:$G$3,0)),"") -> 5 | K6: =IFERROR(AVERAGE(D6:H6),"") -> 12 | L6: =12 -> 12
B7: Total Revenue | C7: VND bn | D7: 122958 | E7: 133405 | F7: 118280 | G7: 134341 | H7: 155928 | I7: 46462 | J7: =IFERROR(INDEX('96_Raw_Phase4_Drivers'!$E$4:$G$180,MATCH("group_revenue_5m_2026",'96_Raw_Phase4_Drivers'!$B$4:$B$180,0),MATCH("Base",'96_Raw_Phase4_Drivers'!$E$3:$G$3,0)),"") -> 79159 | K7: =IFERROR(IF(AND(D7>0,H7>0),(H7/D7)^(1/4)-1,""),"") -> 0.061186776 | L7: ='07_Revenue_Drivers'!G8 -> 185000
B8: YoY Revenue Growth | C8: % | E8: =IFERROR(E7/D7-1,"") -> 0.084963971 | F8: =IFERROR(F7/E7-1,"") -> -0.11337656 | G8: =IFERROR(G7/F7-1,"") -> 0.13578796 | H8: =IFERROR(H7/G7-1,"") -> 0.1606881 | J8: =IFERROR(IFERROR(INDEX('96_Raw_Phase4_Drivers'!$E$4:$G$180,MATCH("group_revenue_5m_2026",'96_Raw_Phase4_Drivers'!$B$4:$B$180,0),MATCH("Base",'96_Raw_Phase4_Drivers'!$E$3:$G$3,0)),"")/IFERROR(INDEX('96_Raw_Phase4_Drivers'!$E$4:$G$180,MATCH("group_revenue_5m_2025",'96_Raw_Phase4_Drivers'!$B$4:$B$180,0),MATCH("Base",'96_Raw_Phase4_Drivers'!$E$3:$G$3,0)),"")-1,"") -> 0.29283509 | K8: =IFERROR(AVERAGE(E8:H8),"") -> 0.067015868 | L8: =IFERROR(L7/H7-1,"") -> 0.18644503
B9: NPAT | C9: VND bn | D9: 4901 | E9: 4102 | F9: 168 | G9: 3733 | H9: =IFERROR('90_Raw_IS_vnstock'!C22/1000000000,0) -> 7072.6229 | I9: 2757.6 | K9: =IFERROR(IF(AND(D9>0,H9>0),(H9/D9)^(1/4)-1,""),"") -> 0.096033806 | L9: =IFERROR(INDEX('96_Raw_Phase4_Drivers'!$E$4:$G$180,MATCH("npat_target_2026",'96_Raw_Phase4_Drivers'!$B$4:$B$180,0),MATCH("Base",'96_Raw_Phase4_Drivers'!$E$3:$G$3,0)),"") -> 9200
B10: Online Revenue | C10: VND bn | D10: 14370 | E10: 18930 | F10: 16899 | G10: 9600 | H10: 9200 | I10: 3000 | J10: =IFERROR(INDEX('96_Raw_Phase4_Drivers'!$E$4:$G$180,MATCH("superapp_online_revenue_5m_2026",'96_Raw_Phase4_Drivers'!$B$4:$B$180,0),MATCH("Base",'96_Raw_Phase4_Drivers'!$E$3:$G$3,0)),"") -> 6000 | K10: =IFERROR(IF(AND(D10>0,H10>0),(H10/D10)^(1/4)-1,""),"") -> -0.10549502 | L10: ='07_Revenue_Drivers'!G11 -> 12950
B11: Online Mix | C11: % | D11: =IF(D10="","",IFERROR(D10/D7,"")) -> 0.11686917 | E11: =IF(E10="","",IFERROR(E10/E7,"")) -> 0.14189873 | F11: =IF(F10="","",IFERROR(F10/F7,"")) -> 0.14287284 | G11: =IF(G10="","",IFERROR(G10/G7,"")) -> 0.071459941 | H11: =IF(H10="","",IFERROR(H10/H7,"")) -> 0.05900159 | I11: =IF(I10="","",IFERROR(I10/I7,"")) -> 0.064568895 | J11: =IFERROR(J10/J7,"") -> 0.075796814 | K11: =IFERROR(AVERAGE(D11:H11),"") -> 0.10642046 | L11: =IFERROR(L10/L7,"") -> 0.07
A12: REVENUE BY CHAIN
B13: TGDĐ / TopZone Revenue | C13: VND bn | D13: 31600.206 | E13: 35000 | F13: 28000 | G13: 30000 | H13: 37300 | I13: 10872 | J13: =IFERROR(J7*IFERROR(INDEX('96_Raw_Phase4_Drivers'!$E$4:$G$180,MATCH("tgd_mix_5m_2026",'96_Raw_Phase4_Drivers'!$B$4:$B$180,0),MATCH("Base",'96_Raw_Phase4_Drivers'!$E$3:$G$3,0)),""),"") -> 17810.775 | K13: =IFERROR(IF(AND(D13>0,H13>0),(H13/D13)^(1/4)-1,""),"") -> 0.04232878 | L13: ='07_Revenue_Drivers'!G15 -> 39325.945
B14: ĐMX Revenue | C14: VND bn | D14: 62708.58 | E14: 69000 | F14: 55000 | G14: 59500 | H14: 68400 | I14: 21512 | J14: =IFERROR(J7*IFERROR(INDEX('96_Raw_Phase4_Drivers'!$E$4:$G$180,MATCH("dmx_mix_5m_2026",'96_Raw_Phase4_Drivers'!$B$4:$B$180,0),MATCH("Base",'96_Raw_Phase4_Drivers'!$E$3:$G$3,0)),""),"") -> 36650.617 | K14: =IFERROR(IF(AND(D14>0,H14>0),(H14/D14)^(1/4)-1,""),"") -> 0.021956202 | L14: ='07_Revenue_Drivers'!G16 -> 80924.055
B15: BHX Revenue | C15: VND bn | D15: 28200 | E15: 27000 | F15: 31600 | G15: 41100 | H15: 46900 | I15: 13100 | J15: =IFERROR(J7*IFERROR(INDEX('96_Raw_Phase4_Drivers'!$E$4:$G$180,MATCH("bhx_mix_5m_2026",'96_Raw_Phase4_Drivers'!$B$4:$B$180,0),MATCH("Base",'96_Raw_Phase4_Drivers'!$E$3:$G$3,0)),""),"") -> 23114.428 | K15: =IFERROR(IF(AND(D15>0,H15>0),(H15/D15)^(1/4)-1,""),"") -> 0.13561451 | L15: ='07_Revenue_Drivers'!G17 -> 55500
B16: An Khang Revenue | C16: VND bn | E16: 1500 | F16: 2200 | G16: 2300 | H16: 2200 | K16: =IFERROR(IF(AND(E16>0,H16>0),(H16/E16)^(1/3)-1,""),"") -> 0.13617128 | L16: ='07_Revenue_Drivers'!G18 -> 2860
B17: AVAKids Revenue | C17: VND bn | E17: 600 | F17: 900 | G17: 1200 | H17: 1400 | K17: =IFERROR(IF(AND(E17>0,H17>0),(H17/E17)^(1/3)-1,""),"") -> 0.3263524 | L17: ='07_Revenue_Drivers'!G19 -> 1680
B18: EraBlue Revenue | C18: VND bn
B19: Other / Unallocated / Rounding | C19: VND bn | D19: =IFERROR(D7-SUM(D13:D18),"") -> 449.214 | E19: =IFERROR(E7-SUM(E13:E18),"") -> 305 | F19: =IFERROR(F7-SUM(F13:F18),"") -> 580 | G19: =IFERROR(G7-SUM(G13:G18),"") -> 241 | H19: =IFERROR(H7-SUM(H13:H18),"") -> -272 | I19: =IFERROR(I7-SUM(I13:I18),"") -> 978 | J19: =IFERROR(J7-SUM(J13:J18),"") -> 1583.18 | K19: =IFERROR(AVERAGE(D19:H19),"") -> 260.6428 | L19: ='07_Revenue_Drivers'!G20 -> 4710
B20: Revenue Check: Segment Sum - Total Revenue | C20: VND bn | D20: =IFERROR(SUM(D13:D19)-D7,"") -> 0 | E20: =IFERROR(SUM(E13:E19)-E7,"") -> 0 | F20: =IFERROR(SUM(F13:F19)-F7,"") -> 0 | G20: =IFERROR(SUM(G13:G19)-G7,"") -> 0 | H20: =IFERROR(SUM(H13:H19)-H7,"") -> 0 | I20: =IFERROR(SUM(I13:I19)-I7,"") -> 0 | J20: =IFERROR(SUM(J13:J19)-J7,"") -> 0 | K20: =IFERROR(AVERAGE(D20:H20),"") -> 0 | L20: =IFERROR(SUM(L13:L19)-L7,"") -> 0
A21: REVENUE MIX BY CHAIN
B22: TGDĐ / TopZone Mix | C22: % | D22: =IF(D13="","",IFERROR(D13/D7,"")) -> 0.257 | E22: =IF(E13="","",IFERROR(E13/E7,"")) -> 0.26235898 | F22: =IF(F13="","",IFERROR(F13/F7,"")) -> 0.23672641 | G22: =IF(G13="","",IFERROR(G13/G7,"")) -> 0.22331232 | H22: =IF(H13="","",IFERROR(H13/H7,"")) -> 0.23921297 | I22: =IF(I13="","",IFERROR(I13/I7,"")) -> 0.23399768 | J22: =IF(J13<>"",IFERROR(J13/J$7,""),"") -> 0.225 | K22: =IFERROR(AVERAGE(D22:H22),"") -> 0.24372214 | L22: =IF(L13<>"",IFERROR(L13/L$7,""),"") -> 0.21257267
B23: ĐMX Mix | C23: % | D23: =IF(D14="","",IFERROR(D14/D7,"")) -> 0.51 | E23: =IF(E14="","",IFERROR(E14/E7,"")) -> 0.51722199 | F23: =IF(F14="","",IFERROR(F14/F7,"")) -> 0.46499831 | G23: =IF(G14="","",IFERROR(G14/G7,"")) -> 0.44290276 | H23: =IF(H14="","",IFERROR(H14/H7,"")) -> 0.438664 | I23: =IF(I14="","",IFERROR(I14/I7,"")) -> 0.46300202 | J23: =IF(J14<>"",IFERROR(J14/J$7,""),"") -> 0.463 | K23: =IFERROR(AVERAGE(D23:H23),"") -> 0.47475741 | L23: =IF(L14<>"",IFERROR(L14/L$7,""),"") -> 0.43742733
B24: BHX Mix | C24: % | D24: =IF(D15="","",IFERROR(D15/D7,"")) -> 0.22934661 | E24: =IF(E15="","",IFERROR(E15/E7,"")) -> 0.20239121 | F24: =IF(F15="","",IFERROR(F15/F7,"")) -> 0.26716266 | G24: =IF(G15="","",IFERROR(G15/G7,"")) -> 0.30593787 | H24: =IF(H15="","",IFERROR(H15/H7,"")) -> 0.30077985 | I24: =IF(I15="","",IFERROR(I15/I7,"")) -> 0.28195084 | J24: =IF(J15<>"",IFERROR(J15/J$7,""),"") -> 0.292 | K24: =IFERROR(AVERAGE(D24:H24),"") -> 0.26112364 | L24: =IF(L15<>"",IFERROR(L15/L$7,""),"") -> 0.3
B25: An Khang Mix | C25: % | D25: =IF(D16="","",IFERROR(D16/D7,"")) | E25: =IF(E16="","",IFERROR(E16/E7,"")) -> 0.011243956 | F25: =IF(F16="","",IFERROR(F16/F7,"")) -> 0.018599932 | G25: =IF(G16="","",IFERROR(G16/G7,"")) -> 0.017120611 | H25: =IF(H16="","",IFERROR(H16/H7,"")) -> 0.014109076 | I25: =IF(I16="","",IFERROR(I16/I7,"")) | J25: =IF(J16<>"",IFERROR(J16/J$7,""),"") | K25: =IFERROR(AVERAGE(D25:H25),"") -> 0.015268394 | L25: =IF(L16<>"",IFERROR(L16/L$7,""),"") -> 0.015459459
B26: AVAKids Mix | C26: % | D26: =IF(D17="","",IFERROR(D17/D7,"")) | E26: =IF(E17="","",IFERROR(E17/E7,"")) -> 0.0044975825 | F26: =IF(F17="","",IFERROR(F17/F7,"")) -> 0.0076090632 | G26: =IF(G17="","",IFERROR(G17/G7,"")) -> 0.0089324927 | H26: =IF(H17="","",IFERROR(H17/H7,"")) -> 0.0089785029 | I26: =IF(I17="","",IFERROR(I17/I7,"")) | J26: =IF(J17<>"",IFERROR(J17/J$7,""),"") | K26: =IFERROR(AVERAGE(D26:H26),"") -> 0.0075044103 | L26: =IF(L17<>"",IFERROR(L17/L$7,""),"") -> 0.0090810811
B27: Other / Rounding Mix | C27: % | D27: =IF(D19="","",IFERROR(D19/D7,"")) -> 0.0036533938 | E27: =IF(E19="","",IFERROR(E19/E7,"")) -> 0.0022862711 | F27: =IF(F19="","",IFERROR(F19/F7,"")) -> 0.0049036185 | G27: =IF(G19="","",IFERROR(G19/G7,"")) -> 0.0017939423 | H27: =IF(H19="","",IFERROR(H19/H7,"")) -> -0.0017443948 | I27: =IF(I19="","",IFERROR(I19/I7,"")) -> 0.02104946 | J27: =IF(J18<>"",IFERROR(J18/J$7,""),"") | K27: =IFERROR(AVERAGE(D27:H27),"") -> 0.0021785662 | L27: =IF(L18<>"",IFERROR(L18/L$7,""),"")
A28: ENDING STORE COUNT BY CHAIN
B29: TGDĐ / TopZone Stores | C29: stores | D29: 970 | E29: 1190 | F29: 1078 | G29: 1021 | H29: 1012 | I29: 1014 | J29: =IFERROR(INDEX('96_Raw_Phase4_Drivers'!$E$4:$G$180,MATCH("tgd_stores_5m_2026",'96_Raw_Phase4_Drivers'!$B$4:$B$180,0),MATCH("Base",'96_Raw_Phase4_Drivers'!$E$3:$G$3,0)),"") -> 1012 | K29: =IFERROR(IF(AND(D29>0,H29>0),(H29/D29)^(1/4)-1,""),"") -> 0.010653291 | L29: ='07_Revenue_Drivers'!G32 -> 1012
B30: ĐMX Stores | C30: stores | D30: 1992 | E30: 2284 | F30: 2190 | G30: 2026 | H30: 2008 | I30: 2006 | J30: =IFERROR(INDEX('96_Raw_Phase4_Drivers'!$E$4:$G$180,MATCH("dmx_stores_5m_2026",'96_Raw_Phase4_Drivers'!$B$4:$B$180,0),MATCH("Base",'96_Raw_Phase4_Drivers'!$E$3:$G$3,0)),"") -> 2004 | K30: =IFERROR(IF(AND(D30>0,H30>0),(H30/D30)^(1/4)-1,""),"") -> 0.002002012 | L30: ='07_Revenue_Drivers'!G33 -> 2004
B31: BHX Stores | C31: stores | D31: 2106 | E31: 1728 | F31: 1698 | G31: 1770 | H31: 2559 | I31: 2839 | J31: =IFERROR(INDEX('96_Raw_Phase4_Drivers'!$E$4:$G$180,MATCH("bhx_stores_5m_2026",'96_Raw_Phase4_Drivers'!$B$4:$B$180,0),MATCH("Base",'96_Raw_Phase4_Drivers'!$E$3:$G$3,0)),"") -> 3051 | K31: =IFERROR(IF(AND(D31>0,H31>0),(H31/D31)^(1/4)-1,""),"") -> 0.049912194 | L31: ='07_Revenue_Drivers'!G34 -> 3559
B32: An Khang Stores | C32: stores | D32: 178 | E32: 500 | F32: 527 | G32: 326 | H32: 382 | I32: 409 | J32: =IFERROR(INDEX('96_Raw_Phase4_Drivers'!$E$4:$G$180,MATCH("ak_stores_5m_2026",'96_Raw_Phase4_Drivers'!$B$4:$B$180,0),MATCH("Base",'96_Raw_Phase4_Drivers'!$E$3:$G$3,0)),"") -> 416 | K32: =IFERROR(IF(AND(D32>0,H32>0),(H32/D32)^(1/4)-1,""),"") -> 0.21034963 | L32: ='07_Revenue_Drivers'!G35 -> 482
B33: AVAKids Stores | C33: stores | D33: 0 | E33: 64 | F33: 64 | G33: 62 | H33: 83 | I33: 95 | J33: =IFERROR(INDEX('96_Raw_Phase4_Drivers'!$E$4:$G$180,MATCH("ava_stores_5m_2026",'96_Raw_Phase4_Drivers'!$B$4:$B$180,0),MATCH("Base",'96_Raw_Phase4_Drivers'!$E$3:$G$3,0)),"") -> 95 | K33: =IFERROR(IF(AND(E33>0,H33>0),(H33/E33)^(1/3)-1,""),"") -> 0.090517668 | L33: ='07_Revenue_Drivers'!G36 -> 95
B34: EraBlue Stores | C34: stores | D34: 0 | E34: 5 | F34: 38 | G34: 87 | H34: 181 | I34: 212 | J34: =IFERROR(INDEX('96_Raw_Phase4_Drivers'!$E$4:$G$180,MATCH("erablue_stores_5m_2026",'96_Raw_Phase4_Drivers'!$B$4:$B$180,0),MATCH("Base",'96_Raw_Phase4_Drivers'!$E$3:$G$3,0)),"") -> 245 | K34: =IFERROR(IF(AND(E34>0,H34>0),(H34/E34)^(1/3)-1,""),"") -> 2.3080306 | L34: ='07_Revenue_Drivers'!G37 -> 300
B35: Total Stores - Modeled Chains | C35: stores | D35: =SUM(D29:D34) -> 5246 | E35: =SUM(E29:E34) -> 5771 | F35: =SUM(F29:F34) -> 5595 | G35: =SUM(G29:G34) -> 5292 | H35: =SUM(H29:H34) -> 6225 | I35: =SUM(I29:I34) -> 6575 | J35: =SUM(J29:J34) -> 6823 | K35: =IFERROR(IF(AND(D35>0,H35>0),(H35/D35)^(1/4)-1,""),"") -> 0.043705008 | L35: =SUM(L29:L34) -> 7452
A36: REVENUE / STORE / MONTH
B37: TGDĐ / TopZone Rev/Store/Month | C37: VND bn/store/month | D37: =IF(OR(D13="",D29=0),"",IFERROR(D13/D29/D6,"")) -> 2.7147943 | E37: =IF(OR(E13="",E29=0),"",IFERROR(E13/AVERAGE(D29,E29)/E6,"")) -> 2.7006173 | F37: =IF(OR(F13="",F29=0),"",IFERROR(F13/AVERAGE(E29,F29)/F6,"")) -> 2.0576132 | G37: =IF(OR(G13="",G29=0),"",IFERROR(G13/AVERAGE(F29,G29)/G6,"")) -> 2.3820867 | H37: =IF(OR(H13="",H29=0),"",IFERROR(H13/AVERAGE(G29,H29)/H6,"")) -> 3.0578783 | I37: =IF(OR(I13="",I29=0),"",IFERROR(I13/AVERAGE(H29,I29)/I6,"")) -> 3.5774926 | J37: =IF(OR(J13="",J29=0),"",IFERROR(J13/AVERAGE(H29,J29)/J$6,"")) -> 3.519916 | K37: =IFERROR(IF(AND(D37>0,H37>0),(H37/D37)^(1/4)-1,""),"") -> 0.030198273 | L37: ='07_Revenue_Drivers'!G48 -> 3.2383024
B38: ĐMX Rev/Store/Month | C38: VND bn/store/month | D38: =IF(OR(D14="",D30=0),"",IFERROR(D14/D30/D6,"")) -> 2.6233509 | E38: =IF(OR(E14="",E30=0),"",IFERROR(E14/AVERAGE(D30,E30)/E6,"")) -> 2.6894294 | F38: =IF(OR(F14="",F30=0),"",IFERROR(F14/AVERAGE(E30,F30)/F6,"")) -> 2.048875 | G38: =IF(OR(G14="",G30=0),"",IFERROR(G14/AVERAGE(F30,G30)/G6,"")) -> 2.3521505 | H38: =IF(OR(H14="",H30=0),"",IFERROR(H14/AVERAGE(G30,H30)/H6,"")) -> 2.8259792 | I38: =IF(OR(I14="",I30=0),"",IFERROR(I14/AVERAGE(H30,I30)/I6,"")) -> 3.5728284 | J38: =IF(OR(J14="",J30=0),"",IFERROR(J14/AVERAGE(H30,J30)/J$6,"")) -> 3.6540994 | K38: =IFERROR(IF(AND(D38>0,H38>0),(H38/D38)^(1/4)-1,""),"") -> 0.01877468 | L38: ='07_Revenue_Drivers'!G49 -> 3.3617504
B39: BHX Rev/Store/Month | C39: VND bn/store/month | D39: =IF(OR(D15="",D31=0),"",IFERROR(D15/D31/D6,"")) -> 1.1158594 | E39: =IF(OR(E15="",E31=0),"",IFERROR(E15/AVERAGE(D31,E31)/E6,"")) -> 1.1737089 | F39: =IF(OR(F15="",F31=0),"",IFERROR(F15/AVERAGE(E31,F31)/F6,"")) -> 1.5372641 | G39: =IF(OR(G15="",G31=0),"",IFERROR(G15/AVERAGE(F31,G31)/G6,"")) -> 1.9752018 | H39: =IF(OR(H15="",H31=0),"",IFERROR(H15/AVERAGE(G31,H31)/H6,"")) -> 1.8056518 | I39: =IF(OR(I15="",I31=0),"",IFERROR(I15/AVERAGE(H31,I31)/I6,"")) -> 1.6178832 | J39: =IF(OR(J15="",J31=0),"",IFERROR(J15/AVERAGE(H31,J31)/J$6,"")) -> 1.6480876 | K39: =IFERROR(IF(AND(D39>0,H39>0),(H39/D39)^(1/4)-1,""),"") -> 0.12786242 | L39: ='07_Revenue_Drivers'!G50 -> 1.511932
B40: An Khang Rev/Store/Month | C40: VND bn/store/month | D40: =IF(OR(D16="",D32=0),"",IFERROR(D16/D32/D6,"")) | E40: =IF(OR(E16="",E32=0),"",IFERROR(E16/AVERAGE(D32,E32)/E6,"")) -> 0.36873156 | F40: =IF(OR(F16="",F32=0),"",IFERROR(F16/AVERAGE(E32,F32)/F6,"")) -> 0.35702694 | G40: =IF(OR(G16="",G32=0),"",IFERROR(G16/AVERAGE(F32,G32)/G6,"")) -> 0.44939429 | H40: =IF(OR(H16="",H32=0),"",IFERROR(H16/AVERAGE(G32,H32)/H6,"")) -> 0.51789077 | I40: =IF(OR(I16="",I32=0),"",IFERROR(I16/AVERAGE(H32,I32)/I6,"")) | J40: =IF(OR(J16="",J32=0),"",IFERROR(J16/AVERAGE(H32,J32)/J$6,"")) | K40: =IFERROR(IF(AND(E40>0,H40>0),(H40/E40)^(1/3)-1,""),"") -> 0.11989151 | L40: ='07_Revenue_Drivers'!G51 -> 0.55169753
B41: AVAKids Rev/Store/Month | C41: VND bn/store/month | D41: =IF(OR(D17="",D33=0),"",IFERROR(D17/D33/D6,"")) | E41: =IF(OR(E17="",E33=0),"",IFERROR(E17/AVERAGE(D33,E33)/E6,"")) -> 1.5625 | F41: =IF(OR(F17="",F33=0),"",IFERROR(F17/AVERAGE(E33,F33)/F6,"")) -> 1.171875 | G41: =IF(OR(G17="",G33=0),"",IFERROR(G17/AVERAGE(F33,G33)/G6,"")) -> 1.5873016 | H41: =IF(OR(H17="",H33=0),"",IFERROR(H17/AVERAGE(G33,H33)/H6,"")) -> 1.6091954 | I41: =IF(OR(I17="",I33=0),"",IFERROR(I17/AVERAGE(H33,I33)/I6,"")) | J41: =IF(OR(J17="",J33=0),"",IFERROR(J17/AVERAGE(H33,J33)/J$6,"")) | K41: =IFERROR(IF(AND(E41>0,H41>0),(H41/E41)^(1/3)-1,""),"") -> 0.0098640661 | L41: ='07_Revenue_Drivers'!G52 -> 1.5730337
...

Sheet 07_Revenue_Drivers
A1: MWG - Revenue Driver Forecast
A2: Forecast period: 2026E-2030E | Unit: VND bn unless stated | Green = linked history/raw source | Blue = scenario selector/source inputs | Black = formulas. 2026E Base is calibrated to company guidance; 2027E+ uses store count x revenue/store/month drivers.
B3: Selected Scenario | D3: Base
A5: Section | B5: Line Item | C5: Unit | D5: 2025A | E5: 3M2026A | F5: 5M2026A | G5: 2026E | H5: 2027E | I5: 2028E | J5: 2029E | K5: 2030E
A6: GROUP SUMMARY
A7: GROUP SUMMARY | B7: Months represented | C7: months | D7: ='06_Revenue_Drivers_Hist'!H6 -> 12 | E7: ='06_Revenue_Drivers_Hist'!I6 -> 3 | F7: =IFERROR(INDEX('96_Raw_Phase4_Drivers'!$E$4:$G$180,MATCH("latest_months",'96_Raw_Phase4_Drivers'!$B$4:$B$180,0),MATCH($D$3,'96_Raw_Phase4_Drivers'!$E$3:$G$3,0)),"") -> 5 | G7: =12 -> 12 | H7: =12 -> 12 | I7: =12 -> 12 | J7: =12 -> 12 | K7: =12 -> 12
A8: GROUP SUMMARY | B8: Total Revenue | C8: VND bn | D8: ='06_Revenue_Drivers_Hist'!H7 -> 155928 | E8: ='06_Revenue_Drivers_Hist'!I7 -> 46462 | F8: =IFERROR(INDEX('96_Raw_Phase4_Drivers'!$E$4:$G$180,MATCH("group_revenue_5m_2026",'96_Raw_Phase4_Drivers'!$B$4:$B$180,0),MATCH($D$3,'96_Raw_Phase4_Drivers'!$E$3:$G$3,0)),"") -> 79159 | G8: =IFERROR(INDEX('96_Raw_Phase4_Drivers'!$E$4:$G$180,MATCH("group_revenue_target_2026",'96_Raw_Phase4_Drivers'!$B$4:$B$180,0),MATCH($D$3,'96_Raw_Phase4_Drivers'!$E$3:$G$3,0)),"") -> 185000 | H8: =SUM(H15:H20) -> 210702.27 | I8: =SUM(I15:I20) -> 232016.74 | J8: =SUM(J15:J20) -> 250797.07 | K8: =SUM(K15:K20) -> 267230.44
A9: GROUP SUMMARY | B9: YoY Revenue Growth | C9: % | D9: =IFERROR(D8/'06_Revenue_Drivers_Hist'!G7-1,"") -> 0.1606881 | F9: =IFERROR(F8/INDEX('96_Raw_Phase4_Drivers'!$E$4:$G$180,MATCH("group_revenue_5m_2025",'96_Raw_Phase4_Drivers'!$B$4:$B$180,0),MATCH($D$3,'96_Raw_Phase4_Drivers'!$E$3:$G$3,0))-1,"") -> 0.29283509 | G9: =IFERROR(G8/D8-1,"") -> 0.18644503 | H9: =IFERROR(H8/G8-1,"") -> 0.13893119 | I9: =IFERROR(I8/H8-1,"") -> 0.10115916 | J9: =IFERROR(J8/I8-1,"") -> 0.08094389 | K9: =IFERROR(K8/J8-1,"") -> 0.065524566
A10: GROUP SUMMARY | B10: 2026 target completion | C10: % | F10: =IFERROR(F8/INDEX('96_Raw_Phase4_Drivers'!$E$4:$G$180,MATCH("group_revenue_target_2026",'96_Raw_Phase4_Drivers'!$B$4:$B$180,0),MATCH($D$3,'96_Raw_Phase4_Drivers'!$E$3:$G$3,0)),"") -> 0.42788649 | G10: =1 -> 1
A11: GROUP SUMMARY | B11: Online / Super App Revenue | C11: VND bn | D11: ='06_Revenue_Drivers_Hist'!H10 -> 9200 | E11: ='06_Revenue_Drivers_Hist'!I10 -> 3000 | F11: =IFERROR(INDEX('96_Raw_Phase4_Drivers'!$E$4:$G$180,MATCH("superapp_online_revenue_5m_2026",'96_Raw_Phase4_Drivers'!$B$4:$B$180,0),MATCH($D$3,'96_Raw_Phase4_Drivers'!$E$3:$G$3,0)),"") -> 6000 | G11: =G8*INDEX('96_Raw_Phase4_Drivers'!$E$4:$G$180,MATCH("online_mix_2026",'96_Raw_Phase4_Drivers'!$B$4:$B$180,0),MATCH($D$3,'96_Raw_Phase4_Drivers'!$E$3:$G$3,0)) -> 12950 | H11: =H8*INDEX('96_Raw_Phase4_Drivers'!$E$4:$G$180,MATCH("online_mix_2027",'96_Raw_Phase4_Drivers'!$B$4:$B$180,0),MATCH($D$3,'96_Raw_Phase4_Drivers'!$E$3:$G$3,0)) -> 15802.67 | I11: =I8*INDEX('96_Raw_Phase4_Drivers'!$E$4:$G$180,MATCH("online_mix_2028",'96_Raw_Phase4_Drivers'!$B$4:$B$180,0),MATCH($D$3,'96_Raw_Phase4_Drivers'!$E$3:$G$3,0)) -> 18561.339 | J11: =J8*INDEX('96_Raw_Phase4_Drivers'!$E$4:$G$180,MATCH("online_mix_2029",'96_Raw_Phase4_Drivers'!$B$4:$B$180,0),MATCH($D$3,'96_Raw_Phase4_Drivers'!$E$3:$G$3,0)) -> 21317.751 | K11: =K8*INDEX('96_Raw_Phase4_Drivers'!$E$4:$G$180,MATCH("online_mix_2030",'96_Raw_Phase4_Drivers'!$B$4:$B$180,0),MATCH($D$3,'96_Raw_Phase4_Drivers'!$E$3:$G$3,0)) -> 24050.74
A12: GROUP SUMMARY | B12: Online / Super App Mix | C12: % | D12: =IFERROR(D11/D8,"") -> 0.05900159 | E12: =IFERROR(E11/E8,"") -> 0.064568895 | F12: =IFERROR(F11/F8,"") -> 0.075796814 | G12: =IFERROR(G11/G8,"") -> 0.07 | H12: =IFERROR(H11/H8,"") -> 0.075 | I12: =IFERROR(I11/I8,"") -> 0.08 | J12: =IFERROR(J11/J8,"") -> 0.085 | K12: =IFERROR(K11/K8,"") -> 0.09
A14: REVENUE BY CHAIN
A15: REVENUE BY CHAIN | B15: TGDD / TopZone Revenue | C15: VND bn | D15: ='06_Revenue_Drivers_Hist'!H13 -> 37300 | E15: ='06_Revenue_Drivers_Hist'!I13 -> 10872 | F15: =F8*INDEX('96_Raw_Phase4_Drivers'!$E$4:$G$180,MATCH("tgd_mix_5m_2026",'96_Raw_Phase4_Drivers'!$B$4:$B$180,0),MATCH($D$3,'96_Raw_Phase4_Drivers'!$E$3:$G$3,0)) -> 17810.775 | G15: =(G8*INDEX('96_Raw_Phase4_Drivers'!$E$4:$G$180,MATCH("core_revenue_mix_2026",'96_Raw_Phase4_Drivers'!$B$4:$B$180,0),MATCH($D$3,'96_Raw_Phase4_Drivers'!$E$3:$G$3,0)))*INDEX('96_Raw_Phase4_Drivers'!$E$4:$G$180,MATCH("tgd_mix_5m_2026",'96_Raw_Phase4_Drivers'!$B$4:$B$180,0),MATCH($D$3,'96_Raw_Phase4_Drivers'!$E$3:$G$3,0))/(INDEX('96_Raw_Phase4_Drivers'!$E$4:$G$180,MATCH("tgd_mix_5m_2026",'96_Raw_Phase4_Drivers'!$B$4:$B$180,0),MATCH($D$3,'96_Raw_Phase4_Drivers'!$E$3:$G$3,0))+INDEX('96_Raw_Phase4_Drivers'!$E$4:$G$180,MATCH("dmx_mix_5m_2026",'96_Raw_Phase4_Drivers'!$B$4:$B$180,0),MATCH($D$3,'96_Raw_Phase4_Drivers'!$E$3:$G$3,0))) -> 39325.945 | H15: =H41*H48*12 -> 40898.983 | I15: =I41*I48*12 -> 42125.952 | J15: =J41*J48*12 -> 43389.731 | K15: =K41*K48*12 -> 44474.474
A16: REVENUE BY CHAIN | B16: DMX Revenue | C16: VND bn | D16: ='06_Revenue_Drivers_Hist'!H14 -> 68400 | E16: ='06_Revenue_Drivers_Hist'!I14 -> 21512 | F16: =F8*INDEX('96_Raw_Phase4_Drivers'!$E$4:$G$180,MATCH("dmx_mix_5m_2026",'96_Raw_Phase4_Drivers'!$B$4:$B$180,0),MATCH($D$3,'96_Raw_Phase4_Drivers'!$E$3:$G$3,0)) -> 36650.617 | G16: =(G8*INDEX('96_Raw_Phase4_Drivers'!$E$4:$G$180,MATCH("core_revenue_mix_2026",'96_Raw_Phase4_Drivers'!$B$4:$B$180,0),MATCH($D$3,'96_Raw_Phase4_Drivers'!$E$3:$G$3,0)))*INDEX('96_Raw_Phase4_Drivers'!$E$4:$G$180,MATCH("dmx_mix_5m_2026",'96_Raw_Phase4_Drivers'!$B$4:$B$180,0),MATCH($D$3,'96_Raw_Phase4_Drivers'!$E$3:$G$3,0))/(INDEX('96_Raw_Phase4_Drivers'!$E$4:$G$180,MATCH("tgd_mix_5m_2026",'96_Raw_Phase4_Drivers'!$B$4:$B$180,0),MATCH($D$3,'96_Raw_Phase4_Drivers'!$E$3:$G$3,0))+INDEX('96_Raw_Phase4_Drivers'!$E$4:$G$180,MATCH("dmx_mix_5m_2026",'96_Raw_Phase4_Drivers'!$B$4:$B$180,0),MATCH($D$3,'96_Raw_Phase4_Drivers'!$E$3:$G$3,0))) -> 80924.055 | H16: =H42*H49*12 -> 85693.976 | I16: =I42*I49*12 -> 89978.674 | J16: =J42*J49*12 -> 93577.821 | K16: =K42*K49*12 -> 96385.156
